Workbook
Name All_general_buildings__and_structures: Sheet2!$B$5
Name Buildings_and_structures_presenting_a_low_degree_of_hazard_to_life_and_property__in_the_event_of_failure__such_as_isolated_towers_in_wooded_areas__farm_buildings_other_than_residential_buildings__etc.: Sheet2!$B$7
Name Important_buildings_and_structures_such_as__hospitals__communication_buildings__towers_and_power_plant_structures: Sheet2!$B$8
Name Temporary_sheds__structures_such_as_those__used_during_construction_operations__for_example__formwork_and_false_work___structures_during_construction_stages__and_boundary_walls: Sheet2!$B$6

Sheet Sheet1
A1: WIND PRESSURE CALCULATION
A3: Location ( city) | B3: Surat | D3: Topography (ө) | E3: 3
A4: Basic Wind Speed (Vb) | B4: =IF(B3="Select a City",0,VLOOKUP(B3,Sheet3!A5:B81,2)) -> 44 | D4: Height of Hill (Z) | E4: 900
A5: Class of structure | B5: D | D5: Crest (X) | E5: 200
A6: Life of Building | B6: =VLOOKUP(B5,Sheet2!A6:H9,2) -> 50
A7: Terrain category | B7: 3 | D7: Shape of building | E7: Rectangular
A8: Height of Building (h) | B8: 30
A9: Width of Building (a) | B9: 24
A10: Length of Building (b) | B10: 18
A11: Height of Storey | B11: 3
A12: Bay width | B12: 3
A13: Tributary Area | B13: =B11*B8 -> 90
A16: Height of Building | B16: Vb | C16: K1 | D16: K2 | E16: K3 | F16: K4 | G16: Vz | H16: Pz | I16: Ka | J16: kd | K16: kc | L16: Pd
A17: =IF(B8<=10,B8,IF(B8>10,10,0)) -> 10 | B17: =$B$4 -> 44 | C17: =Sheet2!$C$11 -> 1 | D17: =IF(AND($B$7=1,OR(A17=10,A17<10)),Sheet2!M3,IF(AND($B$7=2,OR(A17=10,A17<10)),Sheet2!N3,IF(AND($B$7=3,OR(A17=10,A17<10)),Sheet2!O3,IF(AND($B$7=4,OR(A17=10,A17<10)),Sheet2!P3,IF(AND($B$7=1,A17<10),Sheet2!T7,IF(AND($B$7=2,A17<10,Sheet2!T7,IF(AND($B$7=3,A17<10),Sheet2!T7,IF(AND($B$7=4,A17<10),Sheet2!T7,0))),0)))))) -> 0.91 | E17: =Sheet2!$K$30 -> 1 | F17: 1 | G17: =B17*C17*D17*E17*F17 -> 40.04 | H17: =(0.6*G17^2)/1000 -> 0.96192096 | I17: =Sheet2!$I$56 -> 0.81333333 | J17: =Sheet2!$B$61 -> 0.9 | K17: 1 | L17: =H17*I17*J17*K17 -> 0.70412614
A18: =IF(B8<=15,B8,IF(B8>15,15,0)) -> 15 | B18: =$B$4 -> 44 | C18: =Sheet2!$C$11 -> 1 | D18: =IF(AND($B$7=1,OR(A18=15,10<A18<15)),Sheet2!M4,IF(AND($B$7=2,OR(A18=15,10<A18<15)),Sheet2!N4,IF(AND($B$7=3,OR(A18=15,10<A18<15)),Sheet2!O4,IF(AND($B$7=4,OR(A18=15,10<A20<15)),Sheet2!P4,Sheet2!$T$7)))) -> 0.97 | E18: =Sheet2!$K$30 -> 1 | F18: 1 | G18: =B18*C18*D18*E18*F18 -> 42.68 | H18: =(0.6*G18^2)/1000 -> 1.0929494 | I18: =Sheet2!$I$56 -> 0.81333333 | J18: =Sheet2!$B$61 -> 0.9 | K18: 1 | L18: =H18*I18*J18*K18 -> 0.80003899
A19: =IF(B8<=20,B8,IF(B8>20,20,0)) -> 20 | B19: =$B$4 -> 44 | C19: =Sheet2!$C$11 -> 1 | D19: =IF(AND($B$7=1,OR(A19=20,15<A19<20)),Sheet2!M5,IF(AND($B$7=2,OR(A19=20,15<A19<20)),Sheet2!N5,IF(AND($B$7=3,OR(A19=20,15<A19<20)),Sheet2!O5,IF(AND($B$7=4,OR(A19=20,15<A19<20)),Sheet2!P5,Sheet2!$T$7)))) -> 1.01 | E19: =Sheet2!$K$30 -> 1 | F19: 1 | G19: =B19*C19*D19*E19*F19 -> 44.44 | H19: =(0.6*G19^2)/1000 -> 1.1849482 | I19: =Sheet2!$I$56 -> 0.81333333 | J19: =Sheet2!$B$61 -> 0.9 | K19: 1 | L19: =H19*I19*J19*K19 -> 0.86738205
A20: =IF(B8<=30,B8,IF(B8>30,30,0)) -> 30 | B20: =$B$4 -> 44 | C20: =Sheet2!$C$11 -> 1 | D20: =IF(AND($B$7=1,OR(A20=30,20<A20<30)),Sheet2!M6,IF(AND($B$7=2,OR(A20=30,20<A20<30)),Sheet2!N6,IF(AND($B$7=3,OR(A20=30,20<A20<30)),Sheet2!O6,IF(AND($B$7=4,OR(A20=30,20<A20<30)),Sheet2!P6,Sheet2!$T$7)))) -> 1.06 | E20: =Sheet2!$K$30 -> 1 | F20: 1 | G20: =B20*C20*D20*E20*F20 -> 46.64 | H20: =(0.6*G20^2)/1000 -> 1.3051738 | I20: =Sheet2!$I$56 -> 0.81333333 | J20: =Sheet2!$B$61 -> 0.9 | K20: 1 | L20: =H20*I20*J20*K20 -> 0.95538719

Sheet Sheet2
A1: Table 1: Risk coefficients for different classes of structures in different wind speed zones [Clause 5.3.1] | I1: =IF(B14=33,3,IF(B14=39,4,IF(B14=44,5,IF(B14=47,6,IF(B14=50,7,IF(B14=55,8,0)))))) -> 5 | L1: Height (z) | M1: Terrain and height multiplier (k2) | T1: =IF(T5=1,2,IF(T5=2,3,IF(T5=3,4,IF(T5=4,5,0)))) -> 4
L2: (m) | M2: 1 | N2: 2 | O2: 3 | P2: 4
L3: 10 | M3: 1.05 | N3: 1 | O3: 0.91 | P3: 0.8
A4: Class of Structure | B4: Mean Probable design life (years) | C4: Basic wind speed Vb (m/s) | L4: 15 | M4: 1.09 | N4: 1.05 | O4: 0.97 | P4: 0.8 | S4: Height of Building | T4: =Sheet1!B8 -> 30
C5: 33 | D5: 39 | E5: 44 | F5: 47 | G5: 50 | H5: 55 | L5: 20 | M5: 1.12 | N5: 1.07 | O5: 1.01 | P5: 0.8 | S5: Terrain category | T5: =Sheet1!B7 -> 3
A6: A | B6: 5 | C6: 0.82 | D6: 0.76 | E6: 0.73 | F6: 0.71 | G6: 0.7 | H6: 0.67 | L6: 30 | M6: 1.15 | N6: 1.12 | O6: 1.06 | P6: 0.97
A7: B | B7: 25 | C7: 0.94 | D7: 0.92 | E7: 0.91 | F7: 0.9 | G7: 0.9 | H7: 0.89 | L7: 50 | M7: 1.2 | N7: 1.17 | O7: 1.12 | P7: 1.1 | S7: K2 | T7: =T14 -> 1.06
A8: C | B8: 100 | C8: 1.05 | D8: 1.06 | E8: 1.07 | F8: 1.07 | G8: 1.08 | H8: 1.08 | L8: 100 | M8: 1.26 | N8: 1.24 | O8: 1.2 | P8: 1.2
A9: D | B9: 50 | C9: 1 | D9: 1 | E9: 1 | F9: 1 | G9: 1 | H9: 1 | L9: 150 | M9: 1.3 | N9: 1.28 | O9: 1.24 | P9: 1.24 | S9: X | T9: =T4 -> 30
A10: Select a Class | L10: 200 | M10: 1.32 | N10: 1.3 | O10: 1.27 | P10: 1.27 | S10: X1 | T10: =IF(T9>=500,500,IF(T9>450,450,IF(T9>400,400,IF(T9>350,350,IF(T9>300,300,IF(T9>250,250,IF(T9>200,200,IF(T9>150,150,IF(T9>100,100,IF(T9>50,50,IF(T9>30,30,IF(T9>20,20,IF(T9>15,15,IF(T9>10,10,IF(T9>=0,0,0))))))))))))))) -> 20
B11: k1 | C11: =VLOOKUP(B13,A6:H9,I1) -> 1 | L11: 250 | M11: 1.34 | N11: 1.32 | O11: 1.29 | P11: 1.28 | S11: X2 | T11: =IF(T9<=10,10,IF(T9<=15,15,IF(T9<=20,20,IF(T9<=30,30,IF(T9<=50,50,IF(T9<=100,100,IF(T9<=150,150,IF(T9<=200,200,IF(T9<=250,250,IF(T9<=300,300,IF(T9<=350,350,IF(T9<=400,400,IF(T9<=450,450,IF(T9<=500,500,0)))))))))))))) -> 30
A12: Life of Building | B12: =Sheet1!B6 -> 50 | L12: 300 | M12: 1.35 | N12: 1.34 | O12: 1.31 | P12: 1.3 | S12: Y1 | T12: =IF(T5=1,VLOOKUP(T9,L3:P16,T1),IF(T5=2,VLOOKUP(T9,L3:P16,T1),IF(T5=3,VLOOKUP(T9,L3:P16,T1),IF(T5=4,VLOOKUP(T9,L3:P16,T1),0)))) -> 1.06
A13: Class of structure | B13: =Sheet1!B5 -> D | L13: 350 | M13: 1.37 | N13: 1.36 | O13: 1.32 | P13: 1.31 | S13: Y2 | T13: =IF(T5=1,VLOOKUP(T11,L3:P16,T1),IF(T5=2,VLOOKUP(T11,L3:P16,T1),IF(T5=3,VLOOKUP(T11,L3:P16,T1),IF(T5=4,VLOOKUP(T11,L3:P16,T1))))) -> 1.06
A14: Basic Wind Speed (Vb) | B14: =Sheet1!B4 -> 44 | L14: 400 | M14: 1.38 | N14: 1.37 | O14: 1.34 | P14: 1.32 | S14: Y | T14: =T12+(T13-T12)/(T11-T10)*(T9-T10) -> 1.06
L15: 450 | M15: 1.39 | N15: 1.38 | O15: 1.35 | P15: 1.33
L16: 500 | M16: 1.4 | N16: 1.39 | O16: 1.36 | P16: 1.34
C22: Kc | F22: Topography factor,K3 | P22: Crest | R22: Crest
C23: 1
C24: 0.8 | F24: Slope | G24: Le | I24: Slope | J24: C | K24: =1.2*(G29/G30) -> 0.062889335
C25: 0.8 | F25: 3˚<ө<=17˚ | G25: L | I25: 3˚<ө<=17˚ | J25: 1.2(Z/L)
C26: 0.95 | F26: ө>17˚ | G26: Z/0.3 | I26: ө>17˚ | J26: 0.36
C27: 1
F28: ө | G28: =Sheet1!E3 -> 3 | J28: k3(ө<3) | K28: 1
F29: Z | G29: =Sheet1!E4 -> 900 | J29: k3(ө>3) | K29: =1+G31*G32 -> 1
F30: L | G30: =K31 -> 17173.023 | J30: K3 | K30: =IF(G28<=3,K28,IF(G28>3,K29,0)) -> 1
F31: C | G31: =IF(AND(G28>3,G28<=17),K24,IF(G28>17,J26,0)) -> 0 | J31: L | K31: =G29/TAN(RADIANS(G28)) -> 17173.023
F32: s | G32: 0.7 | O32: -1.5 -1.0 -0.5 0 0 0.5 1.0 1.5 2.0 2.5
J33: X | K33: =Sheet1!E5 -> 200 | O33: Upwind X/Le | R33: Downwind X/Le
J34: H | K34: =(G29*(G30-K33))/G30 -> 889.51844
P35: Factors for cliff and escarpment
J36: X/Le | K36: =K33/G30 -> 0.011646173
J37: H/Le | K37: =K34/G30 -> 0.051797429
P39: Crest | R39: Crest
E46: Area averaging factor (Ka)
E48: Tributary Area (A) (m2) | F48: Area | H48: 6
F49: Averaging | O49: -1.5 -1.0 -0.5 0 0 0.5 1.0 1.5 2.0 2.5
F50: Factor (Ka) | O50: Upwind X/Le | R50: Downwind X/Le
E51: 10 | F51: 1 | H51: X | I51: =Sheet1!B13 -> 90 | P51: Factors for ridge and hill
E52: 25 | F52: 0.9 | H52: X1 | I52: =IF(I51>100,100,IF(I51>25,25,IF(I51>10,10,IF(I51<0,0,0)))) -> 25
E53: 100 | F53: 0.8 | H53: X2 | I53: =IF(I51<=10,10,IF(I51<=25,25,IF(100>I51>=100,100,0))) -> 100
...

Sheet Sheet3
A1: Basic Wind Speed at 10m Height for some Important Cities/Towns
A3: City/Town | B3: Basic Wind Speed (m/s)
A4: Select a City | B4: 0
A5: Agra | B5: 47 | C5: Uttar pradesh
A6: Ahmedabad | B6: 39 | C6: Gujrat
A7: Ajmer | B7: 47 | C7: rajasthan
A8: Almora | B8: 47 | C8: Uttarakhand
A9: Amritsar | B9: 47 | C9: Punjab
A10: Asansol | B10: 47 | C10: West Bengal
A11: Aurangabad | B11: 39 | C11: Maharashtra
A12: Bahraich | B12: 47 | C12: Uttar pradesh
A13: Bangalore | B13: 33 | C13: Karnataka
A14: Barauni | B14: 47 | C14: Bihar
A15: Bhatinda | B15: 47 | C15: Punjab
A16: Bhilai | B16: 39 | C16: Chhattisgarh
... A81: Visakhapatnam | B81: 50 | C81: Andhra pradesh

Sheet Sheet7
A1: State | B1: =Sheet1!B3 -> Surat
A2: Andaman and Nicobar | B2: =VLOOKUP(A2,[1]Sheet3!$C$2:$CB$34,MATCH($B$1,[1]Sheet3!$C$1:$CB$1,0),0) -> 0
A3: Andhra pradesh | B3: =VLOOKUP(A3,[1]Sheet3!$C$2:$CB$34,MATCH($B$1,[1]Sheet3!$C$1:$CB$1,0),0) -> 0
A4: Arunachal Pradesh | B4: =VLOOKUP(A4,[1]Sheet3!$C$2:$CB$34,MATCH($B$1,[1]Sheet3!$C$1:$CB$1,0),0) -> 0
A5: Assam | B5: =VLOOKUP(A5,[1]Sheet3!$C$2:$CB$34,MATCH($B$1,[1]Sheet3!$C$1:$CB$1,0),0) -> 0
A6: Bihar | B6: =VLOOKUP(A6,[1]Sheet3!$C$2:$CB$34,MATCH($B$1,[1]Sheet3!$C$1:$CB$1,0),0) -> 0
A7: Chhattisgarh | B7: =VLOOKUP(A7,[1]Sheet3!$C$2:$CB$34,MATCH($B$1,[1]Sheet3!$C$1:$CB$1,0),0) -> 0
A8: Delhi | B8: =VLOOKUP(A8,[1]Sheet3!$C$2:$CB$34,MATCH($B$1,[1]Sheet3!$C$1:$CB$1,0),0) -> 0
A9: Goa | B9: =VLOOKUP(A9,[1]Sheet3!$C$2:$CB$34,MATCH($B$1,[1]Sheet3!$C$1:$CB$1,0),0) -> 0
A10: Gujrat | B10: =VLOOKUP(A10,[1]Sheet3!$C$2:$CB$34,MATCH($B$1,[1]Sheet3!$C$1:$CB$1,0),0) -> 44
A11: Haryana | B11: =VLOOKUP(A11,[1]Sheet3!$C$2:$CB$34,MATCH($B$1,[1]Sheet3!$C$1:$CB$1,0),0) -> 0
A12: Himachal Pradesh | B12: =VLOOKUP(A12,[1]Sheet3!$C$2:$CB$34,MATCH($B$1,[1]Sheet3!$C$1:$CB$1,0),0) -> 0
A13: Jammu and kashmir | B13: =VLOOKUP(A13,[1]Sheet3!$C$2:$CB$34,MATCH($B$1,[1]Sheet3!$C$1:$CB$1,0),0) -> 0
... A34: West Bengal | B34: =VLOOKUP(A34,[1]Sheet3!$C$2:$CB$34,MATCH($B$1,[1]Sheet3!$C$1:$CB$1,0),0) -> 0

Sheet Sheet5
A1: Agra | C1: State | D1: {=TRANSPOSE(A1:A77)} -> Agra | E1: Ahmedabad | F1: Ajmer | G1: Almora | H1: Amritsar | I1: Asansol | J1: Aurangabad | K1: Bahraich | L1: Bangalore | M1: Barauni | N1: Bhatinda | O1: Bhilai | P1: Bhopal | Q1: Bhubaneshwar | R1: Bhuj | S1: Bikaner | T1: Bokaro | U1: Bareilly | V1: Calicut | W1: Chandigarh | X1: Chennai | Y1: Coimbatore | Z1: Cuttack | AA1: Darbhanga | AB1: Darjeeling | AC1: Dehra Dun | AD1: Delhi | AE1: Durgapur | AF1: Gangtok | AG1: Gaya | AH1: Gorakhpur | AI1: Guwahati | AJ1: Hyderabad | AK1: Imphal | AL1: Jabalpur | AM1: Jaipur | AN1: Jamshedpur | AO1: Jhansi | AP1: Jodhpur | AQ1: Kanpur | AR1: Kohima | AS1: Kolkata | AT1: Kurnool | AU1: Lakshadweep | AV1: Lucknow | AW1: Ludhiana | AX1: Madurai | AY1: Mandi | AZ1: Mangalore | BA1: Moradabad | BB1: Mumbai | BC1: Mysore | BD1: Nagpur | BE1: Nainital | BF1: Nasik | BG1: Nellore | BH1: Panjim | BI1: Patiala | BJ1: Patna | BK1: Pondicherry | BL1: Port Blair | BM1: Pune | BN1: Raipur | BO1: Rajkot | BP1: Ranchi | BQ1: Roorkee | BR1: Rourkela | BS1: Shimla | BT1: Srinagar | BU1: Surat | BV1: Tiruchirapalli | BW1: Trivandrum | BX1: Udaipur | BY1: Vadodara | BZ1: Varanasi | CA1: Vijaywada | CB1: Visakhapatnam
A2: Ahmedabad | C2: Andaman and Nicobar | BL2: 44
A3: Ajmer | C3: Andhra pradesh | AT3: 39 | BG3: 50 | CA3: 50 | CB3: 50
A4: Almora | C4: Arunachal Pradesh
A5: Amritsar | C5: Assam | AI5: 50
A6: Asansol | C6: Bihar | M6: 47 | AA6: 55 | AG6: 39 | BJ6: 47
A7: Aurangabad | C7: Chhattisgarh | O7: 39 | BH7: 39 | BN7: 39
A8: Bahraich | C8: Delhi | AD8: 47 | AF8: 47
A9: Bangalore | C9: Goa
A10: Barauni | C10: Gujrat | E10: 39 | R10: 50 | BO10: 39 | BU10: 44 | BY10: 44
A11: Bhatinda | C11: Haryana
A12: Bhilai | C12: Himachal Pradesh | AY12: 39 | BS12: 39
A13: Bhopal | C13: Jammu and kashmir | BT13: 39
A14: Bhubaneshwar | C14: Jharkhand | T14: 47 | AN14: 47 | BP14: 39
A15: Bhuj | C15: Karnataka | L15: 33 | AZ15: 33 | BC15: 33
A16: Bikaner | C16: Kerala | V16: 39 | BW16: 39
A17: Bokaro | C17: Ladakh
A18: Bareilly | C18: Lakshadweep | AU18: 39 | AW18: 47
A19: Calicut | C19: Madhya Pradesh | P19: 39 | AL19: 47 | BF19: 39
A20: Chandigarh | C20: Maharashtra | J20: 39 | BB20: 44 | BD20: 44 | BM20: 39
A21: Chennai | C21: Manipur | AK21: 47
A22: Coimbatore | C22: Meghalaya
A23: Cuttack | C23: Mizoram
A24: Darbhanga | C24: Nagaland | AR24: 44
A25: Darjeeling | C25: Odisha | Q25: 50 | Z25: 50 | BR25: 39
A26: Dehra Dun | C26: Punjab | H26: 47 | N26: 47 | W26: 47 | BI26: 47
A27: Delhi | C27: Rajasthan | F27: 47 | S27: 47 | AM27: 47 | AP27: 47 | BX27: 47
A28: Durgapur | C28: Sikkim
A29: Gangtok | C29: Tamil nadu | X29: 50 | Y29: 39 | AX29: 39 | BK29: 50 | BV29: 47
A30: Gaya | C30: Telangana | AJ30: 44
A31: Gorakhpur | C31: Tripura
A32: Guwahati | C32: Uttar pradesh | D32: 47 | K32: 47 | U32: 47 | AH32: 47 | AO32: 47 | AQ32: 47 | AV32: 47 | BA32: 47 | BZ32: 47
A33: Hyderabad | C33: Uttarakhand | G33: 47 | AC33: 47 | BE33: 47 | BQ33: 39
A34: Imphal | C34: West Bengal | I34: 47 | AB34: 47 | AE34: 47 | AS34: 50
A35: Jabalpur
A36: Jaipur
A37: Jamshedpur
A38: Jhansi
A39: Jodhpur
A40: Kanpur
...

Sheet Sheet6

Sheet Sheet4
B2: FORCE COEFFICIENT (Cf)
A4: a | B4: =Sheet1!B9 -> 24
A5: b | B5: =Sheet1!B10 -> 18
A6: h | B6: =Sheet1!B8 -> 30
A8: a/b | B8: =B4/B5 -> 1.3333333
A9: h/b | B9: =B6/B5 -> 1.6666667
A10: Cf | B10: 1.2
D28: NODE | E28: Area
D29: 1 | E29: =1.5*1.5 -> 2.25
D30: 2 | E30: =1.5*3 -> 4.5
D31: 3 | E31: =3*3 -> 9
H32: Nodal Point Load
C33: Node | D33: Area | E33: Loading Level | G33: Pressure | H33: Node1 | I33: Node2 | J33: Node3
C34: 1,2 | E34: 0 | G34: =Sheet1!L17 -> 0.70412614 | H34: =E29*G34 -> 1.5842838 | I34: =E30*G34 -> 3.1685676
C35: 2,3 | E35: 3 | G35: =Sheet1!L17 -> 0.70412614 | I35: =$E$30*G35 -> 3.1685676 | J35: =$E$31*G35 -> 6.3371353
C36: 2,3 | E36: 6 | G36: =Sheet1!L17 -> 0.70412614 | I36: =$E$30*G36 -> 3.1685676 | J36: =$E$31*G36 -> 6.3371353
C37: 2,3 | E37: 9 | G37: =(G36+G38)/2 -> 0.75208257 | I37: =$E$30*G37 -> 3.3843715 | J37: =$E$31*G37 -> 6.7687431
C38: 2,3 | E38: 12 | G38: =Sheet1!L18 -> 0.80003899 | I38: =$E$30*G38 -> 3.6001755 | J38: =$E$31*G38 -> 7.2003509
C39: 2,3 | E39: 15 | G39: =(G38+G40)/2 -> 0.83371052 | I39: =$E$30*G39 -> 3.7516973 | J39: =$E$31*G39 -> 7.5033947
C40: 2,3 | E40: 18 | G40: =Sheet1!L19 -> 0.86738205 | I40: =$E$30*G40 -> 3.9032192 | J40: =$E$31*G40 -> 7.8064385
C41: 2,3 | E41: 21 | G41: =(G40+G42)/2 -> 0.91138462 | I41: =$E$30*G41 -> 4.1012308 | J41: =$E$31*G41 -> 8.2024616
C42: 2,3 | E42: 24 | G42: =Sheet1!L20 -> 0.95538719 | I42: =$E$30*G42 -> 4.2992424 | J42: =$E$31*G42 -> 8.5984847
C43: 2,3 | E43: 27 | G43: =Sheet1!L20 -> 0.95538719 | I43: =$E$30*G43 -> 4.2992424 | J43: =$E$31*G43 -> 8.5984847
C44: 1,2 | E44: 30 | G44: =Sheet1!L20 -> 0.95538719 | H44: =E29*G44 -> 2.1496212 | I44: =$E$30*G44 -> 4.2992424
A45: Height | B45: F
A46: =Sheet1!A17 -> 10 | B46: 0.553 | E46: X | F46: 30 | H46: X | I46: 14.75 | K46: X | L46: 18.75 | N46: X | O46: 22.75
A47: =Sheet1!A18 -> 15 | B47: 0.61 | E47: X1 | F47: =IF(F46>=50,50,IF(F46>30,30,IF(F46>20,20,IF(F46>15,15,IF(F46>10,10,IF(F46>=0,0,0)))))) -> 20 | H47: X1 | I47: =IF(I46>=50,50,IF(I46>30,30,IF(I46>20,20,IF(I46>15,15,IF(I46>10,10,IF(I46>=0,0,0)))))) -> 10 | K47: X1 | L47: =IF(L46>=50,50,IF(L46>30,30,IF(L46>20,20,IF(L46>15,15,IF(L46>10,10,IF(L46>=0,0,0)))))) -> 15 | N47: X1 | O47: =IF(O46>=50,50,IF(O46>30,30,IF(O46>20,20,IF(O46>15,15,IF(O46>10,10,IF(O46>=0,0,0)))))) -> 20
A48: =Sheet1!A19 -> 20 | B48: 0.633 | E48: X2 | F48: =IF(F46<=10,10,IF(F46<=15,15,IF(F46<=20,20,IF(F46<=30,30,IF(F46<=50,50,0))))) -> 30 | H48: X2 | I48: =IF(I46<=10,10,IF(I46<=15,15,IF(I46<=20,20,IF(I46<=30,30,IF(I46<=50,50,0))))) -> 15 | K48: X2 | L48: =IF(L46<=10,10,IF(L46<=15,15,IF(L46<=20,20,IF(L46<=30,30,IF(L46<=50,50,0))))) -> 20 | N48: X2 | O48: =IF(O46<=10,10,IF(O46<=15,15,IF(O46<=20,20,IF(O46<=30,30,IF(O46<=50,50,0))))) -> 30
A49: =Sheet1!A20 -> 30 | B49: 0.694 | E49: Y1 | F49: =IF(F47=10,$B$46,IF(F47=15,$B$47,IF(F47=20,$B$48,IF(F47=30,$B$49,IF(F47=50,$B$50,0))))) -> 0.633 | H49: Y1 | I49: =IF(I47=10,$B$46,IF(I47=15,$B$47,IF(I47=20,$B$48,IF(I47=30,$B$49,IF(I47=50,$B$50,0))))) -> 0.553 | K49: Y1 | L49: =IF(L47=10,$B$46,IF(L47=15,$B$47,IF(L47=20,$B$48,IF(L47=30,$B$49,IF(L47=50,$B$50,0))))) -> 0.61 | N49: Y1 | O49: =IF(O47=10,$B$46,IF(O47=15,$B$47,IF(O47=20,$B$48,IF(O47=30,$B$49,IF(O47=50,$B$50,0))))) -> 0.633
A50: =Sheet1!B21 -> 0 | B50: 0.694 | E50: Y2 | F50: =IF(F48=10,$B$46,IF(F48=15,$B$47,IF(F48=20,$B$48,IF(F48=30,$B$49,IF(F48=50,$B$50,0))))) -> 0.694 | H50: Y2 | I50: =IF(I48=10,$B$46,IF(I48=15,$B$47,IF(I48=20,$B$48,IF(I48=30,$B$49,IF(I48=50,$B$50,0))))) -> 0.61 | K50: Y2 | L50: =IF(L48=10,$B$46,IF(L48=15,$B$47,IF(L48=20,$B$48,IF(L48=30,$B$49,IF(L48=50,$B$50,0))))) -> 0.633 | N50: Y2 | O50: =IF(O48=10,$B$46,IF(O48=15,$B$47,IF(O48=20,$B$48,IF(O48=30,$B$49,IF(O48=50,$B$50,0))))) -> 0.694
E51: Y | F51: =F49+((F50-F49)/(F48-F47))*(F46-F47) -> 0.694 | H51: Y | I51: =I49+((I50-I49)/(I48-I47))*(I46-I47) -> 0.60715 | K51: Y | L51: =L49+((L50-L49)/(L48-L47))*(L46-L47) -> 0.62725 | N51: Y | O51: =O49+((O50-O49)/(O48-O47))*(O46-O47) -> 0.649775
E53: X | F53: 26.75 | H53: X | I53: 10.75 | K53: X | L53: 10.75 | N53: X | O53: 10.75
E54: X1 | F54: =IF(F53>=50,50,IF(F53>30,30,IF(F53>20,20,IF(F53>15,15,IF(F53>10,10,IF(F53>=0,0,0)))))) -> 20 | H54: X1 | I54: =IF(I53>=50,50,IF(I53>30,30,IF(I53>20,20,IF(I53>15,15,IF(I53>10,10,IF(I53>=0,0,0)))))) -> 10 | K54: X1 | L54: =IF(L53>=50,50,IF(L53>30,30,IF(L53>20,20,IF(L53>15,15,IF(L53>10,10,IF(L53>=0,0,0)))))) -> 10 | N54: X1 | O54: =IF(O53>=50,50,IF(O53>30,30,IF(O53>20,20,IF(O53>15,15,IF(O53>10,10,IF(O53>=0,0,0)))))) -> 10
E55: X2 | F55: =IF(F53<=10,10,IF(F53<=15,15,IF(F53<=20,20,IF(F53<=30,30,IF(F53<=50,50,0))))) -> 30 | H55: X2 | I55: =IF(I53<=10,10,IF(I53<=15,15,IF(I53<=20,20,IF(I53<=30,30,IF(I53<=50,50,0))))) -> 15 | K55: X2 | L55: =IF(L53<=10,10,IF(L53<=15,15,IF(L53<=20,20,IF(L53<=30,30,IF(L53<=50,50,0))))) -> 15 | N55: X2 | O55: =IF(O53<=10,10,IF(O53<=15,15,IF(O53<=20,20,IF(O53<=30,30,IF(O53<=50,50,0))))) -> 15
E56: Y1 | F56: =IF(F54=10,$B$46,IF(F54=15,$B$47,IF(F54=20,$B$48,IF(F54=30,$B$49,IF(F54=50,$B$50,0))))) -> 0.633 | H56: Y1 | I56: =IF(I54=10,$B$46,IF(I54=15,$B$47,IF(I54=20,$B$48,IF(I54=30,$B$49,IF(I54=50,$B$50,0))))) -> 0.553 | K56: Y1 | L56: =IF(L54=10,$B$46,IF(L54=15,$B$47,IF(L54=20,$B$48,IF(L54=30,$B$49,IF(L54=50,$B$50,0))))) -> 0.553 | N56: Y1 | O56: =IF(O54=10,$B$46,IF(O54=15,$B$47,IF(O54=20,$B$48,IF(O54=30,$B$49,IF(O54=50,$B$50,0))))) -> 0.553
E57: Y2 | F57: =IF(F55=10,$B$46,IF(F55=15,$B$47,IF(F55=20,$B$48,IF(F55=30,$B$49,IF(F55=50,$B$50,0))))) -> 0.694 | H57: Y2 | I57: =IF(I55=10,$B$46,IF(I55=15,$B$47,IF(I55=20,$B$48,IF(I55=30,$B$49,IF(I55=50,$B$50,0))))) -> 0.61 | K57: Y2 | L57: =IF(L55=10,$B$46,IF(L55=15,$B$47,IF(L55=20,$B$48,IF(L55=30,$B$49,IF(L55=50,$B$50,0))))) -> 0.61 | N57: Y2 | O57: =IF(O55=10,$B$46,IF(O55=15,$B$47,IF(O55=20,$B$48,IF(O55=30,$B$49,IF(O55=50,$B$50,0))))) -> 0.61
E58: Y | F58: =F56+((F57-F56)/(F55-F54))*(F53-F54) -> 0.674175 | H58: Y | I58: =I56+((I57-I56)/(I55-I54))*(I53-I54) -> 0.56155 | K58: Y | L58: =L56+((L57-L56)/(L55-L54))*(L53-L54) -> 0.56155 | N58: Y | O58: =O56+((O57-O56)/(O55-O54))*(O53-O54) -> 0.56155
